Workbook

Sheet Settings
A1: South Africa Shift Roster & Claims Tool
A3: Purpose | B3: Auto-roster 8-hour shifts, capture claims, calculate overtime/standby, and flag BCEA compliance risks.
A5: Key Assumption / Control | B5: Value | C5: Notes | E5: Workbook Features
A6: Roster Start Date | B6: 46143 | C6: Change this to the first roster day. | E6: 1. Automated 8-hour shift rotation from Rotation_Pattern and Employees sheets.
A7: Roster Days | B7: 31 | C7: Auto_Roster currently supports up to 31 days. | E7: 2. Compliance checks: >45 ordinary hrs/wk, >10 overtime hrs/wk, short daily rest, meal break flag, approval required.
A8: Standard Shift Hours | B8: 8 | C8: User-requested 8-hour rotation per person per day. | E8: 3. Payroll-ready claim calculations for normal, overtime, Sunday/holiday, standby and night allowance inputs.
A9: Weekly Ordinary Hours Limit | B9: 45 | C9: BCEA ordinary hours limit. | E9: 4. Dashboard with employee totals and charts.
A10: Weekly Overtime Limit | B10: 10 | C10: BCEA overtime limit. | E10: Boost: claim status workflow, public holiday register, weekly exceptions list and data-validation controls.
A11: Daily Rest Minimum Hours | B11: 12 | C11: BCEA minimum rest between shifts.
A12: Weekly Rest Minimum Hours | B12: 36 | C12: BCEA weekly rest guidance.
A13: Overtime Multiplier | B13: 1.5 | C13: Default BCEA overtime pay multiplier; confirm contract/sector rules.
A14: Sunday Multiplier | B14: 2 | C14: Default Sunday pay input; adjust to company policy / contract.
A15: Public Holiday Multiplier | B15: 2 | C15: Default public holiday input; adjust to company policy / contract.
A16: Standby Allowance Per Day | B16: 250 | C16: Input amount for standby claim per standby day.
A17: Night Shift Allowance Per Hour | B17: 0 | C17: Optional allowance; set per company policy.
A18: Default Hourly Rate | B18: 100 | C18: Fallback if employee-specific rate is blank.
A19: Approval Required Above Hours | B19: 8 | C19: Claims over this daily number are flagged for approval.

Sheet Employees
A1: Employee Master
A3: Employee ID | B3: Employee Name | C3: Team | D3: Role | E3: Hourly Rate | F3: Eligible for OT? | G3: Eligible for Standby? | H3: Active? | I3: Notes
A4: E001 | B4: Musiwa Khavalani | D4: Operator | E4: 100 | F4: Y | G4: Y | H4: Y
A5: E002 | B5: Mpho Nembemhia | C5: B | D5: Operator | E5: 100 | F5: Y | G5: Y | H5: Y
A6: E003 | B6: Dimpho Makhafola | C6: C | D6: Operator | E6: 100 | F6: Y | G6: Y | H6: Y
A7: E004 | B7: Bashii Fall | C7: D | D7: Operator | E7: 100 | F7: Y | G7: Y | H7: Y
A8: E005 | B8: Lesego Aphane | C8: A | D8: Operator | E8: 100 | F8: Y | G8: Y | H8: Y
A9: E006 | B9: Nhalnahla | C9: B | D9: Operator | E9: 100 | F9: Y | G9: Y | H9: Y
A10: E007 | B10: Joe | C10: C | D10: Operator | E10: 100 | G10: Y | H10: Y
A11: E008 | B11: Tim | C11: D | D11: Operator | E11: 100 | G11: Y | H11: Y
A12: E009 | B12: Frank | C12: A | D12: Operator | E12: 100 | G12: Y | H12: Y

Sheet Rotation_Pattern
A1: Rotation Pattern Logic
A3: Cycle Day | B3: Team A | C3: Team B | D3: Team C | E3: Team D | F3: Shift Start | G3: Shift End | H3: Notes
A4: 1 | B4: Day | C4: Off | D4: Evening | E4: Night | F4: 06:00 | G4: 14:00 | H4: 8-hour block
A5: 2 | B5: Evening | C5: Day | D5: Off | E5: Night | F5: 14:00 | G5: 22:00 | H5: 8-hour block
A6: 3 | B6: Night | C6: Evening | D6: Day | E6: Off | F6: 22:00 | G6: 06:00 | H6: Crosses midnight
A7: 4 | B7: Off | C7: Night | D7: Evening | E7: Day | H7: Rest day
A10: How it works
A11: Auto_Roster calculates cycle day using MOD(Date - Start Date, 4) + 1, then maps each employee team to this pattern. Update this sheet if your rotation differs.

Sheet Public_Holidays
A1: Public Holiday Register
A3: Date | B3: Holiday Name | C3: Source / Notes | D3: Add / Adjust
A4: 46023 | B4: New Year's Day | C4: South Africa public holiday | D4: Input
A5: 46102 | B5: Human Rights Day | C5: South Africa public holiday | D5: Input
A6: 46115 | B6: Good Friday | C6: South Africa public holiday | D6: Input
A7: 46118 | B7: Family Day | C7: South Africa public holiday | D7: Input
A8: 46139 | B8: Freedom Day | C8: South Africa public holiday | D8: Input
A9: 46143 | B9: Workers' Day | C9: South Africa public holiday | D9: Input
A10: 46189 | B10: Youth Day | C10: South Africa public holiday | D10: Input
A11: 46243 | B11: National Women's Day | C11: South Africa public holiday | D11: Input
A12: 46244 | B12: Public holiday observed | C12: Because 9 Aug falls on Sunday | D12: Input
A13: 46289 | B13: Heritage Day | C13: South Africa public holiday | D13: Input
A14: 46372 | B14: Day of Reconciliation | C14: South Africa public holiday | D14: Input
A15: 46381 | B15: Christmas Day | C15: South Africa public holiday | D15: Input
A16: 46382 | B16: Day of Goodwill | C16: South Africa public holiday | D16: Input

Sheet Auto_Roster
A1: Automated 8-Hour Shift Roster
A3: Date | B3: Week Start | C3: Employee ID | D3: Employee Name | E3: Team | F3: Cycle Day | G3: Auto Shift | H3: Shift Start | I3: Shift End | J3: Shift Hours | K3: Standby? | L3: Public Holiday? | M3: Sunday? | N3: Compliance Flags | O3: Approval Status | P3: Notes
A4: =IF(0+1<=Settings!$B$7,Settings!$B$6+0,"") -> 46143 | B4: =IF(A4="","",A4-WEEKDAY(A4,2)+1) -> 46139 | C4: =IF(Employees!A4="","",Employees!A4) -> E001 | D4: =IF(C4="","",Employees!B4) -> Musiwa Khavalani | E4: =IF(C4="","",Employees!C4) -> 0 | F4: =IF(A4="","",MOD(A4-Settings!$B$6,4)+1) -> 1 | G4: =IF(C4="","",INDEX(Rotation_Pattern!$B$4:$E$7,F4,MATCH(E4,{"A","B","C","D"},0))) -> #N/A | H4: =IF(OR(G4="Off",G4=""),"",IF(G4="Day",TIME(6,0,0),IF(G4="Evening",TIME(14,0,0),TIME(22,0,0)))) -> #N/A | I4: =IF(OR(G4="Off",G4=""),"",H4+TIME(Settings!$B$8,0,0)) -> #N/A | J4: =IF(OR(G4="Off",G4=""),0,Settings!$B$8) -> #N/A | K4: N | L4: =IF(A4="","",IF(COUNTIF(Public_Holidays!$A$4:$A$80,A4)>0,"Y","N")) -> Y | M4: =IF(A4="","",IF(WEEKDAY(A4,2)=7,"Y","N")) -> N | N4: =IF(A4="","",_xlfn.TEXTJOIN("; ",TRUE,IF(SUMIFS($J:$J,$C:$C,C4,$B:$B,B4)>Settings!$B$9,"Weekly ordinary hrs >45",""),IF(SUMIFS(Claims!$H:$H,Claims!$C:$C,C4,Claims!$B:$B,B4)>Settings!$B$10,"Weekly OT >10",""),IF(AND(G4<>"Off",COUNTIFS($C:$C,C4,$A:$A,A4-1,$G:$G,"Night")>0),"Rest <12h after night shift",""),IF(J4>5,"Meal interval required",""))) -> #N/A | O4: Pending
A5: =IF(0+1<=Settings!$B$7,Settings!$B$6+0,"") -> 46143 | B5: =IF(A5="","",A5-WEEKDAY(A5,2)+1) -> 46139 | C5: =IF(Employees!A5="","",Employees!A5) -> E002 | D5: =IF(C5="","",Employees!B5) -> Mpho Nembemhia | E5: =IF(C5="","",Employees!C5) -> B | F5: =IF(A5="","",MOD(A5-Settings!$B$6,4)+1) -> 1 | G5: =IF(C5="","",INDEX(Rotation_Pattern!$B$4:$E$7,F5,MATCH(E5,{"A","B","C","D"},0))) -> Off | H5: =IF(OR(G5="Off",G5=""),"",IF(G5="Day",TIME(6,0,0),IF(G5="Evening",TIME(14,0,0),TIME(22,0,0)))) | I5: =IF(OR(G5="Off",G5=""),"",H5+TIME(Settings!$B$8,0,0)) | J5: =IF(OR(G5="Off",G5=""),0,Settings!$B$8) -> 0 | K5: N | L5: =IF(A5="","",IF(COUNTIF(Public_Holidays!$A$4:$A$80,A5)>0,"Y","N")) -> Y | M5: =IF(A5="","",IF(WEEKDAY(A5,2)=7,"Y","N")) -> N | N5: =IF(A5="","",_xludf.TEXTJOIN("; ",TRUE,IF(SUMIFS($J:$J,$C:$C,C5,$B:$B,B5)>Settings!$B$9,"Weekly ordinary hrs >45",""),IF(SUMIFS(Claims!$H:$H,Claims!$C:$C,C5,Claims!$B:$B,B5)>Settings!$B$10,"Weekly OT >10",""),IF(AND(G5<>"Off",COUNTIFS($C:$C,C5,$A:$A,A5-1,$G:$G,"Night")>0),"Rest <12h after night shift",""),IF(J5>5,"Meal interval required",""))) -> #NAME? | O5: Pending
A6: =IF(0+1<=Settings!$B$7,Settings!$B$6+0,"") -> 46143 | B6: =IF(A6="","",A6-WEEKDAY(A6,2)+1) -> 46139 | C6: =IF(Employees!A6="","",Employees!A6) -> E003 | D6: =IF(C6="","",Employees!B6) -> Dimpho Makhafola | E6: =IF(C6="","",Employees!C6) -> C | F6: =IF(A6="","",MOD(A6-Settings!$B$6,4)+1) -> 1 | G6: =IF(C6="","",INDEX(Rotation_Pattern!$B$4:$E$7,F6,MATCH(E6,{"A","B","C","D"},0))) -> Evening | H6: =IF(OR(G6="Off",G6=""),"",IF(G6="Day",TIME(6,0,0),IF(G6="Evening",TIME(14,0,0),TIME(22,0,0)))) -> 0.58333333 | I6: =IF(OR(G6="Off",G6=""),"",H6+TIME(Settings!$B$8,0,0)) -> 0.91666667 | J6: =IF(OR(G6="Off",G6=""),0,Settings!$B$8) -> 8 | K6: N | L6: =IF(A6="","",IF(COUNTIF(Public_Holidays!$A$4:$A$80,A6)>0,"Y","N")) -> Y | M6: =IF(A6="","",IF(WEEKDAY(A6,2)=7,"Y","N")) -> N | N6: =IF(A6="","",_xludf.TEXTJOIN("; ",TRUE,IF(SUMIFS($J:$J,$C:$C,C6,$B:$B,B6)>Settings!$B$9,"Weekly ordinary hrs >45",""),IF(SUMIFS(Claims!$H:$H,Claims!$C:$C,C6,Claims!$B:$B,B6)>Settings!$B$10,"Weekly OT >10",""),IF(AND(G6<>"Off",COUNTIFS($C:$C,C6,$A:$A,A6-1,$G:$G,"Night")>0),"Rest <12h after night shift",""),IF(J6>5,"Meal interval required",""))) -> #NAME? | O6: Pending
A7: =IF(0+1<=Settings!$B$7,Settings!$B$6+0,"") -> 46143 | B7: =IF(A7="","",A7-WEEKDAY(A7,2)+1) -> 46139 | C7: =IF(Employees!A7="","",Employees!A7) -> E004 | D7: =IF(C7="","",Employees!B7) -> Bashii Fall | E7: =IF(C7="","",Employees!C7) -> D | F7: =IF(A7="","",MOD(A7-Settings!$B$6,4)+1) -> 1 | G7: =IF(C7="","",INDEX(Rotation_Pattern!$B$4:$E$7,F7,MATCH(E7,{"A","B","C","D"},0))) -> Night | H7: =IF(OR(G7="Off",G7=""),"",IF(G7="Day",TIME(6,0,0),IF(G7="Evening",TIME(14,0,0),TIME(22,0,0)))) -> 0.91666667 | I7: =IF(OR(G7="Off",G7=""),"",H7+TIME(Settings!$B$8,0,0)) -> 1.25 | J7: =IF(OR(G7="Off",G7=""),0,Settings!$B$8) -> 8 | K7: N | L7: =IF(A7="","",IF(COUNTIF(Public_Holidays!$A$4:$A$80,A7)>0,"Y","N")) -> Y | M7: =IF(A7="","",IF(WEEKDAY(A7,2)=7,"Y","N")) -> N | N7: =IF(A7="","",_xludf.TEXTJOIN("; ",TRUE,IF(SUMIFS($J:$J,$C:$C,C7,$B:$B,B7)>Settings!$B$9,"Weekly ordinary hrs >45",""),IF(SUMIFS(Claims!$H:$H,Claims!$C:$C,C7,Claims!$B:$B,B7)>Settings!$B$10,"Weekly OT >10",""),IF(AND(G7<>"Off",COUNTIFS($C:$C,C7,$A:$A,A7-1,$G:$G,"Night")>0),"Rest <12h after night shift",""),IF(J7>5,"Meal interval required",""))) -> #NAME? | O7: Pending
A8: =IF(0+1<=Settings!$B$7,Settings!$B$6+0,"") -> 46143 | B8: =IF(A8="","",A8-WEEKDAY(A8,2)+1) -> 46139 | C8: =IF(Employees!A8="","",Employees!A8) -> E005 | D8: =IF(C8="","",Employees!B8) -> Lesego Aphane | E8: =IF(C8="","",Employees!C8) -> A | F8: =IF(A8="","",MOD(A8-Settings!$B$6,4)+1) -> 1 | G8: =IF(C8="","",INDEX(Rotation_Pattern!$B$4:$E$7,F8,MATCH(E8,{"A","B","C","D"},0))) -> Day | H8: =IF(OR(G8="Off",G8=""),"",IF(G8="Day",TIME(6,0,0),IF(G8="Evening",TIME(14,0,0),TIME(22,0,0)))) -> 0.25 | I8: =IF(OR(G8="Off",G8=""),"",H8+TIME(Settings!$B$8,0,0)) -> 0.58333333 | J8: =IF(OR(G8="Off",G8=""),0,Settings!$B$8) -> 8 | K8: N | L8: =IF(A8="","",IF(COUNTIF(Public_Holidays!$A$4:$A$80,A8)>0,"Y","N")) -> Y | M8: =IF(A8="","",IF(WEEKDAY(A8,2)=7,"Y","N")) -> N | N8: =IF(A8="","",_xludf.TEXTJOIN("; ",TRUE,IF(SUMIFS($J:$J,$C:$C,C8,$B:$B,B8)>Settings!$B$9,"Weekly ordinary hrs >45",""),IF(SUMIFS(Claims!$H:$H,Claims!$C:$C,C8,Claims!$B:$B,B8)>Settings!$B$10,"Weekly OT >10",""),IF(AND(G8<>"Off",COUNTIFS($C:$C,C8,$A:$A,A8-1,$G:$G,"Night")>0),"Rest <12h after night shift",""),IF(J8>5,"Meal interval required",""))) -> #NAME? | O8: Pending
A9: =IF(0+1<=Settings!$B$7,Settings!$B$6+0,"") -> 46143 | B9: =IF(A9="","",A9-WEEKDAY(A9,2)+1) -> 46139 | C9: =IF(Employees!A9="","",Employees!A9) -> E006 | D9: =IF(C9="","",Employees!B9) -> Nhalnahla | E9: =IF(C9="","",Employees!C9) -> B | F9: =IF(A9="","",MOD(A9-Settings!$B$6,4)+1) -> 1 | G9: =IF(C9="","",INDEX(Rotation_Pattern!$B$4:$E$7,F9,MATCH(E9,{"A","B","C","D"},0))) -> Off | H9: =IF(OR(G9="Off",G9=""),"",IF(G9="Day",TIME(6,0,0),IF(G9="Evening",TIME(14,0,0),TIME(22,0,0)))) | I9: =IF(OR(G9="Off",G9=""),"",H9+TIME(Settings!$B$8,0,0)) | J9: =IF(OR(G9="Off",G9=""),0,Settings!$B$8) -> 0 | K9: N | L9: =IF(A9="","",IF(COUNTIF(Public_Holidays!$A$4:$A$80,A9)>0,"Y","N")) -> Y | M9: =IF(A9="","",IF(WEEKDAY(A9,2)=7,"Y","N")) -> N | N9: =IF(A9="","",_xludf.TEXTJOIN("; ",TRUE,IF(SUMIFS($J:$J,$C:$C,C9,$B:$B,B9)>Settings!$B$9,"Weekly ordinary hrs >45",""),IF(SUMIFS(Claims!$H:$H,Claims!$C:$C,C9,Claims!$B:$B,B9)>Settings!$B$10,"Weekly OT >10",""),IF(AND(G9<>"Off",COUNTIFS($C:$C,C9,$A:$A,A9-1,$G:$G,"Night")>0),"Rest <12h after night shift",""),IF(J9>5,"Meal interval required",""))) -> #NAME? | O9: Pending
A10: =IF(0+1<=Settings!$B$7,Settings!$B$6+0,"") -> 46143 | B10: =IF(A10="","",A10-WEEKDAY(A10,2)+1) -> 46139 | C10: =IF(Employees!A10="","",Employees!A10) -> E007 | D10: =IF(C10="","",Employees!B10) -> Joe | E10: =IF(C10="","",Employees!C10) -> C | F10: =IF(A10="","",MOD(A10-Settings!$B$6,4)+1) -> 1 | G10: =IF(C10="","",INDEX(Rotation_Pattern!$B$4:$E$7,F10,MATCH(E10,{"A","B","C","D"},0))) -> Evening | H10: =IF(OR(G10="Off",G10=""),"",IF(G10="Day",TIME(6,0,0),IF(G10="Evening",TIME(14,0,0),TIME(22,0,0)))) -> 0.58333333 | I10: =IF(OR(G10="Off",G10=""),"",H10+TIME(Settings!$B$8,0,0)) -> 0.91666667 | J10: =IF(OR(G10="Off",G10=""),0,Settings!$B$8) -> 8 | K10: N | L10: =IF(A10="","",IF(COUNTIF(Public_Holidays!$A$4:$A$80,A10)>0,"Y","N")) -> Y | M10: =IF(A10="","",IF(WEEKDAY(A10,2)=7,"Y","N")) -> N | N10: =IF(A10="","",_xludf.TEXTJOIN("; ",TRUE,IF(SUMIFS($J:$J,$C:$C,C10,$B:$B,B10)>Settings!$B$9,"Weekly ordinary hrs >45",""),IF(SUMIFS(Claims!$H:$H,Claims!$C:$C,C10,Claims!$B:$B,B10)>Settings!$B$10,"Weekly OT >10",""),IF(AND(G10<>"Off",COUNTIFS($C:$C,C10,$A:$A,A10-1,$G:$G,"Night")>0),"Rest <12h after night shift",""),IF(J10>5,"Meal interval required",""))) -> #NAME? | O10: Pending
A11: =IF(0+1<=Settings!$B$7,Settings!$B$6+0,"") -> 46143 | B11: =IF(A11="","",A11-WEEKDAY(A11,2)+1) -> 46139 | C11: =IF(Employees!A11="","",Employees!A11) -> E008 | D11: =IF(C11="","",Employees!B11) -> Tim | E11: =IF(C11="","",Employees!C11) -> D | F11: =IF(A11="","",MOD(A11-Settings!$B$6,4)+1) -> 1 | G11: =IF(C11="","",INDEX(Rotation_Pattern!$B$4:$E$7,F11,MATCH(E11,{"A","B","C","D"},0))) -> Night | H11: =IF(OR(G11="Off",G11=""),"",IF(G11="Day",TIME(6,0,0),IF(G11="Evening",TIME(14,0,0),TIME(22,0,0)))) -> 0.91666667 | I11: =IF(OR(G11="Off",G11=""),"",H11+TIME(Settings!$B$8,0,0)) -> 1.25 | J11: =IF(OR(G11="Off",G11=""),0,Settings!$B$8) -> 8 | K11: N | L11: =IF(A11="","",IF(COUNTIF(Public_Holidays!$A$4:$A$80,A11)>0,"Y","N")) -> Y | M11: =IF(A11="","",IF(WEEKDAY(A11,2)=7,"Y","N")) -> N | N11: =IF(A11="","",_xludf.TEXTJOIN("; ",TRUE,IF(SUMIFS($J:$J,$C:$C,C11,$B:$B,B11)>Settings!$B$9,"Weekly ordinary hrs >45",""),IF(SUMIFS(Claims!$H:$H,Claims!$C:$C,C11,Claims!$B:$B,B11)>Settings!$B$10,"Weekly OT >10",""),IF(AND(G11<>"Off",COUNTIFS($C:$C,C11,$A:$A,A11-1,$G:$G,"Night")>0),"Rest <12h after night shift",""),IF(J11>5,"Meal interval required",""))) -> #NAME? | O11: Pending
A12: =IF(0+1<=Settings!$B$7,Settings!$B$6+0,"") -> 46143 | B12: =IF(A12="","",A12-WEEKDAY(A12,2)+1) -> 46139 | C12: =IF(Employees!A12="","",Employees!A12) -> E009 | D12: =IF(C12="","",Employees!B12) -> Frank | E12: =IF(C12="","",Employees!C12) -> A | F12: =IF(A12="","",MOD(A12-Settings!$B$6,4)+1) -> 1 | G12: =IF(C12="","",INDEX(Rotation_Pattern!$B$4:$E$7,F12,MATCH(E12,{"A","B","C","D"},0))) -> Day | H12: =IF(OR(G12="Off",G12=""),"",IF(G12="Day",TIME(6,0,0),IF(G12="Evening",TIME(14,0,0),TIME(22,0,0)))) -> 0.25 | I12: =IF(OR(G12="Off",G12=""),"",H12+TIME(Settings!$B$8,0,0)) -> 0.58333333 | J12: =IF(OR(G12="Off",G12=""),0,Settings!$B$8) -> 8 | K12: N | L12: =IF(A12="","",IF(COUNTIF(Public_Holidays!$A$4:$A$80,A12)>0,"Y","N")) -> Y | M12: =IF(A12="","",IF(WEEKDAY(A12,2)=7,"Y","N")) -> N | N12: =IF(A12="","",_xludf.TEXTJOIN("; ",TRUE,IF(SUMIFS($J:$J,$C:$C,C12,$B:$B,B12)>Settings!$B$9,"Weekly ordinary hrs >45",""),IF(SUMIFS(Claims!$H:$H,Claims!$C:$C,C12,Claims!$B:$B,B12)>Settings!$B$10,"Weekly OT >10",""),IF(AND(G12<>"Off",COUNTIFS($C:$C,C12,$A:$A,A12-1,$G:$G,"Night")>0),"Rest <12h after night shift",""),IF(J12>5,"Meal interval required",""))) -> #NAME? | O12: Pending
A13: =IF(0+1<=Settings!$B$7,Settings!$B$6+0,"") -> 46143 | B13: =IF(A13="","",A13-WEEKDAY(A13,2)+1) -> 46139 | C13: =IF(Employees!A13="","",Employees!A13) | D13: =IF(C13="","",Employees!B13) | E13: =IF(C13="","",Employees!C13) | F13: =IF(A13="","",MOD(A13-Settings!$B$6,4)+1) -> 1 | G13: =IF(C13="","",INDEX(Rotation_Pattern!$B$4:$E$7,F13,MATCH(E13,{"A","B","C","D"},0))) | H13: =IF(OR(G13="Off",G13=""),"",IF(G13="Day",TIME(6,0,0),IF(G13="Evening",TIME(14,0,0),TIME(22,0,0)))) | I13: =IF(OR(G13="Off",G13=""),"",H13+TIME(Settings!$B$8,0,0)) | J13: =IF(OR(G13="Off",G13=""),0,Settings!$B$8) -> 0 | K13: N | L13: =IF(A13="","",IF(COUNTIF(Public_Holidays!$A$4:$A$80,A13)>0,"Y","N")) -> Y | M13: =IF(A13="","",IF(WEEKDAY(A13,2)=7,"Y","N")) -> N | N13: =IF(A13="","",_xludf.TEXTJOIN("; ",TRUE,IF(SUMIFS($J:$J,$C:$C,C13,$B:$B,B13)>Settings!$B$9,"Weekly ordinary hrs >45",""),IF(SUMIFS(Claims!$H:$H,Claims!$C:$C,C13,Claims!$B:$B,B13)>Settings!$B$10,"Weekly OT >10",""),IF(AND(G13<>"Off",COUNTIFS($C:$C,C13,$A:$A,A13-1,$G:$G,"Night")>0),"Rest <12h after night shift",""),IF(J13>5,"Meal interval required",""))) -> #NAME? | O13: Pending
A14: =IF(0+1<=Settings!$B$7,Settings!$B$6+0,"") -> 46143 | B14: =IF(A14="","",A14-WEEKDAY(A14,2)+1) -> 46139 | C14: =IF(Employees!A14="","",Employees!A14) | D14: =IF(C14="","",Employees!B14) | E14: =IF(C14="","",Employees!C14) | F14: =IF(A14="","",MOD(A14-Settings!$B$6,4)+1) -> 1 | G14: =IF(C14="","",INDEX(Rotation_Pattern!$B$4:$E$7,F14,MATCH(E14,{"A","B","C","D"},0))) | H14: =IF(OR(G14="Off",G14=""),"",IF(G14="Day",TIME(6,0,0),IF(G14="Evening",TIME(14,0,0),TIME(22,0,0)))) | I14: =IF(OR(G14="Off",G14=""),"",H14+TIME(Settings!$B$8,0,0)) | J14: =IF(OR(G14="Off",G14=""),0,Settings!$B$8) -> 0 | K14: N | L14: =IF(A14="","",IF(COUNTIF(Public_Holidays!$A$4:$A$80,A14)>0,"Y","N")) -> Y | M14: =IF(A14="","",IF(WEEKDAY(A14,2)=7,"Y","N")) -> N | N14: =IF(A14="","",_xludf.TEXTJOIN("; ",TRUE,IF(SUMIFS($J:$J,$C:$C,C14,$B:$B,B14)>Settings!$B$9,"Weekly ordinary hrs >45",""),IF(SUMIFS(Claims!$H:$H,Claims!$C:$C,C14,Claims!$B:$B,B14)>Settings!$B$10,"Weekly OT >10",""),IF(AND(G14<>"Off",COUNTIFS($C:$C,C14,$A:$A,A14-1,$G:$G,"Night")>0),"Rest <12h after night shift",""),IF(J14>5,"Meal interval required",""))) -> #NAME? | O14: Pending
A15: =IF(0+1<=Settings!$B$7,Settings!$B$6+0,"") -> 46143 | B15: =IF(A15="","",A15-WEEKDAY(A15,2)+1) -> 46139 | C15: =IF(Employees!A15="","",Employees!A15) | D15: =IF(C15="","",Employees!B15) | E15: =IF(C15="","",Employees!C15) | F15: =IF(A15="","",MOD(A15-Settings!$B$6,4)+1) -> 1 | G15: =IF(C15="","",INDEX(Rotation_Pattern!$B$4:$E$7,F15,MATCH(E15,{"A","B","C","D"},0))) | H15: =IF(OR(G15="Off",G15=""),"",IF(G15="Day",TIME(6,0,0),IF(G15="Evening",TIME(14,0,0),TIME(22,0,0)))) | I15: =IF(OR(G15="Off",G15=""),"",H15+TIME(Settings!$B$8,0,0)) | J15: =IF(OR(G15="Off",G15=""),0,Settings!$B$8) -> 0 | K15: N | L15: =IF(A15="","",IF(COUNTIF(Public_Holidays!$A$4:$A$80,A15)>0,"Y","N")) -> Y | M15: =IF(A15="","",IF(WEEKDAY(A15,2)=7,"Y","N")) -> N | N15: =IF(A15="","",_xludf.TEXTJOIN("; ",TRUE,IF(SUMIFS($J:$J,$C:$C,C15,$B:$B,B15)>Settings!$B$9,"Weekly ordinary hrs >45",""),IF(SUMIFS(Claims!$H:$H,Claims!$C:$C,C15,Claims!$B:$B,B15)>Settings!$B$10,"Weekly OT >10",""),IF(AND(G15<>"Off",COUNTIFS($C:$C,C15,$A:$A,A15-1,$G:$G,"Night")>0),"Rest <12h after night shift",""),IF(J15>5,"Meal interval required",""))) -> #NAME? | O15: Pending
A16: =IF(0+1<=Settings!$B$7,Settings!$B$6+0,"") -> 46143 | B16: =IF(A16="","",A16-WEEKDAY(A16,2)+1) -> 46139 | C16: =IF(Employees!A16="","",Employees!A16) | D16: =IF(C16="","",Employees!B16) | E16: =IF(C16="","",Employees!C16) | F16: =IF(A16="","",MOD(A16-Settings!$B$6,4)+1) -> 1 | G16: =IF(C16="","",INDEX(Rotation_Pattern!$B$4:$E$7,F16,MATCH(E16,{"A","B","C","D"},0))) | H16: =IF(OR(G16="Off",G16=""),"",IF(G16="Day",TIME(6,0,0),IF(G16="Evening",TIME(14,0,0),TIME(22,0,0)))) | I16: =IF(OR(G16="Off",G16=""),"",H16+TIME(Settings!$B$8,0,0)) | J16: =IF(OR(G16="Off",G16=""),0,Settings!$B$8) -> 0 | K16: N | L16: =IF(A16="","",IF(COUNTIF(Public_Holidays!$A$4:$A$80,A16)>0,"Y","N")) -> Y | M16: =IF(A16="","",IF(WEEKDAY(A16,2)=7,"Y","N")) -> N | N16: =IF(A16="","",_xludf.TEXTJOIN("; ",TRUE,IF(SUMIFS($J:$J,$C:$C,C16,$B:$B,B16)>Settings!$B$9,"Weekly ordinary hrs >45",""),IF(SUMIFS(Claims!$H:$H,Claims!$C:$C,C16,Claims!$B:$B,B16)>Settings!$B$10,"Weekly OT >10",""),IF(AND(G16<>"Off",COUNTIFS($C:$C,C16,$A:$A,A16-1,$G:$G,"Night")>0),"Rest <12h after night shift",""),IF(J16>5,"Meal interval required",""))) -> #NAME? | O16: Pending
... A23: =IF(0+1<=Settings!$B$7,Settings!$B$6+0,"") -> 46143 | B23: =IF(A23="","",A23-WEEKDAY(A23,2)+1) -> 46139 | C23: =IF(Employees!A23="","",Employees!A23) | D23: =IF(C23="","",Employees!B23) | E23: =IF(C23="","",Employees!C23) | F23: =IF(A23="","",MOD(A23-Settings!$B$6,4)+1) -> 1 | G23: =IF(C23="","",INDEX(Rotation_Pattern!$B$4:$E$7,F23,MATCH(E23,{"A","B","C","D"},0))) | H23: =IF(OR(G23="Off",G23=""),"",IF(G23="Day",TIME(6,0,0),IF(G23="Evening",TIME(14,0,0),TIME(22,0,0)))) | I23: =IF(OR(G23="Off",G23=""),"",H23+TIME(Settings!$B$8,0,0)) | J23: =IF(OR(G23="Off",G23=""),0,Settings!$B$8) -> 0 | K23: N | L23: =IF(A23="","",IF(COUNTIF(Public_Holidays!$A$4:$A$80,A23)>0,"Y","N")) -> Y | M23: =IF(A23="","",IF(WEEKDAY(A23,2)=7,"Y","N")) -> N | N23: =IF(A23="","",_xludf.TEXTJOIN("; ",TRUE,IF(SUMIFS($J:$J,$C:$C,C23,$B:$B,B23)>Settings!$B$9,"Weekly ordinary hrs >45",""),IF(SUMIFS(Claims!$H:$H,Claims!$C:$C,C23,Claims!$B:$B,B23)>Settings!$B$10,"Weekly OT >10",""),IF(AND(G23<>"Off",COUNTIFS($C:$C,C23,$A:$A,A23-1,$G:$G,"Night")>0),"Rest <12h after night shift",""),IF(J23>5,"Meal interval required",""))) -> #NAME? | O23: Pending
A24: =IF(1+1<=Settings!$B$7,Settings!$B$6+1,"") -> 46144 | B24: =IF(A24="","",A24-WEEKDAY(A24,2)+1) -> 46139 | C24: =IF(Employees!A4="","",Employees!A4) -> E001 | D24: =IF(C24="","",Employees!B4) -> Musiwa Khavalani | E24: =IF(C24="","",Employees!C4) -> 0 | F24: =IF(A24="","",MOD(A24-Settings!$B$6,4)+1) -> 2 | G24: =IF(C24="","",INDEX(Rotation_Pattern!$B$4:$E$7,F24,MATCH(E24,{"A","B","C","D"},0))) -> #N/A | H24: =IF(OR(G24="Off",G24=""),"",IF(G24="Day",TIME(6,0,0),IF(G24="Evening",TIME(14,0,0),TIME(22,0,0)))) -> #N/A | I24: =IF(OR(G24="Off",G24=""),"",H24+TIME(Settings!$B$8,0,0)) -> #N/A | J24: =IF(OR(G24="Off",G24=""),0,Settings!$B$8) -> #N/A | K24: N | L24: =IF(A24="","",IF(COUNTIF(Public_Holidays!$A$4:$A$80,A24)>0,"Y","N")) -> N | M24: =IF(A24="","",IF(WEEKDAY(A24,2)=7,"Y","N")) -> N | N24: =IF(A24="","",_xludf.TEXTJOIN("; ",TRUE,IF(SUMIFS($J:$J,$C:$C,C24,$B:$B,B24)>Settings!$B$9,"Weekly ordinary hrs >45",""),IF(SUMIFS(Claims!$H:$H,Claims!$C:$C,C24,Claims!$B:$B,B24)>Settings!$B$10,"Weekly OT >10",""),IF(AND(G24<>"Off",COUNTIFS($C:$C,C24,$A:$A,A24-1,$G:$G,"Night")>0),"Rest <12h after night shift",""),IF(J24>5,"Meal interval required",""))) -> #NAME? | O24: Pending
A25: =IF(1+1<=Settings!$B$7,Settings!$B$6+1,"") -> 46144 | B25: =IF(A25="","",A25-WEEKDAY(A25,2)+1) -> 46139 | C25: =IF(Employees!A5="","",Employees!A5) -> E002 | D25: =IF(C25="","",Employees!B5) -> Mpho Nembemhia | E25: =IF(C25="","",Employees!C5) -> B | F25: =IF(A25="","",MOD(A25-Settings!$B$6,4)+1) -> 2 | G25: =IF(C25="","",INDEX(Rotation_Pattern!$B$4:$E$7,F25,MATCH(E25,{"A","B","C","D"},0))) -> Day | H25: =IF(OR(G25="Off",G25=""),"",IF(G25="Day",TIME(6,0,0),IF(G25="Evening",TIME(14,0,0),TIME(22,0,0)))) -> 0.25 | I25: =IF(OR(G25="Off",G25=""),"",H25+TIME(Settings!$B$8,0,0)) -> 0.58333333 | J25: =IF(OR(G25="Off",G25=""),0,Settings!$B$8) -> 8 | K25: N | L25: =IF(A25="","",IF(COUNTIF(Public_Holidays!$A$4:$A$80,A25)>0,"Y","N")) -> N | M25: =IF(A25="","",IF(WEEKDAY(A25,2)=7,"Y","N")) -> N | N25: =IF(A25="","",_xludf.TEXTJOIN("; ",TRUE,IF(SUMIFS($J:$J,$C:$C,C25,$B:$B,B25)>Settings!$B$9,"Weekly ordinary hrs >45",""),IF(SUMIFS(Claims!$H:$H,Claims!$C:$C,C25,Claims!$B:$B,B25)>Settings!$B$10,"Weekly OT >10",""),IF(AND(G25<>"Off",COUNTIFS($C:$C,C25,$A:$A,A25-1,$G:$G,"Night")>0),"Rest <12h after night shift",""),IF(J25>5,"Meal interval required",""))) -> #NAME? | O25: Pending
A26: =IF(1+1<=Settings!$B$7,Settings!$B$6+1,"") -> 46144 | B26: =IF(A26="","",A26-WEEKDAY(A26,2)+1) -> 46139 | C26: =IF(Employees!A6="","",Employees!A6) -> E003 | D26: =IF(C26="","",Employees!B6) -> Dimpho Makhafola | E26: =IF(C26="","",Employees!C6) -> C | F26: =IF(A26="","",MOD(A26-Settings!$B$6,4)+1) -> 2 | G26: =IF(C26="","",INDEX(Rotation_Pattern!$B$4:$E$7,F26,MATCH(E26,{"A","B","C","D"},0))) -> Off | H26: =IF(OR(G26="Off",G26=""),"",IF(G26="Day",TIME(6,0,0),IF(G26="Evening",TIME(14,0,0),TIME(22,0,0)))) | I26: =IF(OR(G26="Off",G26=""),"",H26+TIME(Settings!$B$8,0,0)) | J26: =IF(OR(G26="Off",G26=""),0,Settings!$B$8) -> 0 | K26: N | L26: =IF(A26="","",IF(COUNTIF(Public_Holidays!$A$4:$A$80,A26)>0,"Y","N")) -> N | M26: =IF(A26="","",IF(WEEKDAY(A26,2)=7,"Y","N")) -> N | N26: =IF(A26="","",_xludf.TEXTJOIN("; ",TRUE,IF(SUMIFS($J:$J,$C:$C,C26,$B:$B,B26)>Settings!$B$9,"Weekly ordinary hrs >45",""),IF(SUMIFS(Claims!$H:$H,Claims!$C:$C,C26,Claims!$B:$B,B26)>Settings!$B$10,"Weekly OT >10",""),IF(AND(G26<>"Off",COUNTIFS($C:$C,C26,$A:$A,A26-1,$G:$G,"Night")>0),"Rest <12h after night shift",""),IF(J26>5,"Meal interval required",""))) -> #NAME? | O26: Pending
A27: =IF(1+1<=Settings!$B$7,Settings!$B$6+1,"") -> 46144 | B27: =IF(A27="","",A27-WEEKDAY(A27,2)+1) -> 46139 | C27: =IF(Employees!A7="","",Employees!A7) -> E004 | D27: =IF(C27="","",Employees!B7) -> Bashii Fall | E27: =IF(C27="","",Employees!C7) -> D | F27: =IF(A27="","",MOD(A27-Settings!$B$6,4)+1) -> 2 | G27: =IF(C27="","",INDEX(Rotation_Pattern!$B$4:$E$7,F27,MATCH(E27,{"A","B","C","D"},0))) -> Night | H27: =IF(OR(G27="Off",G27=""),"",IF(G27="Day",TIME(6,0,0),IF(G27="Evening",TIME(14,0,0),TIME(22,0,0)))) -> 0.91666667 | I27: =IF(OR(G27="Off",G27=""),"",H27+TIME(Settings!$B$8,0,0)) -> 1.25 | J27: =IF(OR(G27="Off",G27=""),0,Settings!$B$8) -> 8 | K27: N | L27: =IF(A27="","",IF(COUNTIF(Public_Holidays!$A$4:$A$80,A27)>0,"Y","N")) -> N | M27: =IF(A27="","",IF(WEEKDAY(A27,2)=7,"Y","N")) -> N | N27: =IF(A27="","",_xludf.TEXTJOIN("; ",TRUE,IF(SUMIFS($J:$J,$C:$C,C27,$B:$B,B27)>Settings!$B$9,"Weekly ordinary hrs >45",""),IF(SUMIFS(Claims!$H:$H,Claims!$C:$C,C27,Claims!$B:$B,B27)>Settings!$B$10,"Weekly OT >10",""),IF(AND(G27<>"Off",COUNTIFS($C:$C,C27,$A:$A,A27-1,$G:$G,"Night")>0),"Rest <12h after night shift",""),IF(J27>5,"Meal interval required",""))) -> #NAME? | O27: Pending
A28: =IF(1+1<=Settings!$B$7,Settings!$B$6+1,"") -> 46144 | B28: =IF(A28="","",A28-WEEKDAY(A28,2)+1) -> 46139 | C28: =IF(Employees!A8="","",Employees!A8) -> E005 | D28: =IF(C28="","",Employees!B8) -> Lesego Aphane | E28: =IF(C28="","",Employees!C8) -> A | F28: =IF(A28="","",MOD(A28-Settings!$B$6,4)+1) -> 2 | G28: =IF(C28="","",INDEX(Rotation_Pattern!$B$4:$E$7,F28,MATCH(E28,{"A","B","C","D"},0))) -> Evening | H28: =IF(OR(G28="Off",G28=""),"",IF(G28="Day",TIME(6,0,0),IF(G28="Evening",TIME(14,0,0),TIME(22,0,0)))) -> 0.58333333 | I28: =IF(OR(G28="Off",G28=""),"",H28+TIME(Settings!$B$8,0,0)) -> 0.91666667 | J28: =IF(OR(G28="Off",G28=""),0,Settings!$B$8) -> 8 | K28: N | L28: =IF(A28="","",IF(COUNTIF(Public_Holidays!$A$4:$A$80,A28)>0,"Y","N")) -> N | M28: =IF(A28="","",IF(WEEKDAY(A28,2)=7,"Y","N")) -> N | N28: =IF(A28="","",_xludf.TEXTJOIN("; ",TRUE,IF(SUMIFS($J:$J,$C:$C,C28,$B:$B,B28)>Settings!$B$9,"Weekly ordinary hrs >45",""),IF(SUMIFS(Claims!$H:$H,Claims!$C:$C,C28,Claims!$B:$B,B28)>Settings!$B$10,"Weekly OT >10",""),IF(AND(G28<>"Off",COUNTIFS($C:$C,C28,$A:$A,A28-1,$G:$G,"Night")>0),"Rest <12h after night shift",""),IF(J28>5,"Meal interval required",""))) -> #NAME? | O28: Pending
A29: =IF(1+1<=Settings!$B$7,Settings!$B$6+1,"") -> 46144 | B29: =IF(A29="","",A29-WEEKDAY(A29,2)+1) -> 46139 | C29: =IF(Employees!A9="","",Employees!A9) -> E006 | D29: =IF(C29="","",Employees!B9) -> Nhalnahla | E29: =IF(C29="","",Employees!C9) -> B | F29: =IF(A29="","",MOD(A29-Settings!$B$6,4)+1) -> 2 | G29: =IF(C29="","",INDEX(Rotation_Pattern!$B$4:$E$7,F29,MATCH(E29,{"A","B","C","D"},0))) -> Day | H29: =IF(OR(G29="Off",G29=""),"",IF(G29="Day",TIME(6,0,0),IF(G29="Evening",TIME(14,0,0),TIME(22,0,0)))) -> 0.25 | I29: =IF(OR(G29="Off",G29=""),"",H29+TIME(Settings!$B$8,0,0)) -> 0.58333333 | J29: =IF(OR(G29="Off",G29=""),0,Settings!$B$8) -> 8 | K29: N | L29: =IF(A29="","",IF(COUNTIF(Public_Holidays!$A$4:$A$80,A29)>0,"Y","N")) -> N | M29: =IF(A29="","",IF(WEEKDAY(A29,2)=7,"Y","N")) -> N | N29: =IF(A29="","",_xludf.TEXTJOIN("; ",TRUE,IF(SUMIFS($J:$J,$C:$C,C29,$B:$B,B29)>Settings!$B$9,"Weekly ordinary hrs >45",""),IF(SUMIFS(Claims!$H:$H,Claims!$C:$C,C29,Claims!$B:$B,B29)>Settings!$B$10,"Weekly OT >10",""),IF(AND(G29<>"Off",COUNTIFS($C:$C,C29,$A:$A,A29-1,$G:$G,"Night")>0),"Rest <12h after night shift",""),IF(J29>5,"Meal interval required",""))) -> #NAME? | O29: Pending
A30: =IF(1+1<=Settings!$B$7,Settings!$B$6+1,"") -> 46144 | B30: =IF(A30="","",A30-WEEKDAY(A30,2)+1) -> 46139 | C30: =IF(Employees!A10="","",Employees!A10) -> E007 | D30: =IF(C30="","",Employees!B10) -> Joe | E30: =IF(C30="","",Employees!C10) -> C | F30: =IF(A30="","",MOD(A30-Settings!$B$6,4)+1) -> 2 | G30: =IF(C30="","",INDEX(Rotation_Pattern!$B$4:$E$7,F30,MATCH(E30,{"A","B","C","D"},0))) -> Off | H30: =IF(OR(G30="Off",G30=""),"",IF(G30="Day",TIME(6,0,0),IF(G30="Evening",TIME(14,0,0),TIME(22,0,0)))) | I30: =IF(OR(G30="Off",G30=""),"",H30+TIME(Settings!$B$8,0,0)) | J30: =IF(OR(G30="Off",G30=""),0,Settings!$B$8) -> 0 | K30: N | L30: =IF(A30="","",IF(COUNTIF(Public_Holidays!$A$4:$A$80,A30)>0,"Y","N")) -> N | M30: =IF(A30="","",IF(WEEKDAY(A30,2)=7,"Y","N")) -> N | N30: =IF(A30="","",_xludf.TEXTJOIN("; ",TRUE,IF(SUMIFS($J:$J,$C:$C,C30,$B:$B,B30)>Settings!$B$9,"Weekly ordinary hrs >45",""),IF(SUMIFS(Claims!$H:$H,Claims!$C:$C,C30,Claims!$B:$B,B30)>Settings!$B$10,"Weekly OT >10",""),IF(AND(G30<>"Off",COUNTIFS($C:$C,C30,$A:$A,A30-1,$G:$G,"Night")>0),"Rest <12h after night shift",""),IF(J30>5,"Meal interval required",""))) -> #NAME? | O30: Pending
A31: =IF(1+1<=Settings!$B$7,Settings!$B$6+1,"") -> 46144 | B31: =IF(A31="","",A31-WEEKDAY(A31,2)+1) -> 46139 | C31: =IF(Employees!A11="","",Employees!A11) -> E008 | D31: =IF(C31="","",Employees!B11) -> Tim | E31: =IF(C31="","",Employees!C11) -> D | F31: =IF(A31="","",MOD(A31-Settings!$B$6,4)+1) -> 2 | G31: =IF(C31="","",INDEX(Rotation_Pattern!$B$4:$E$7,F31,MATCH(E31,{"A","B","C","D"},0))) -> Night | H31: =IF(OR(G31="Off",G31=""),"",IF(G31="Day",TIME(6,0,0),IF(G31="Evening",TIME(14,0,0),TIME(22,0,0)))) -> 0.91666667 | I31: =IF(OR(G31="Off",G31=""),"",H31+TIME(Settings!$B$8,0,0)) -> 1.25 | J31: =IF(OR(G31="Off",G31=""),0,Settings!$B$8) -> 8 | K31: N | L31: =IF(A31="","",IF(COUNTIF(Public_Holidays!$A$4:$A$80,A31)>0,"Y","N")) -> N | M31: =IF(A31="","",IF(WEEKDAY(A31,2)=7,"Y","N")) -> N | N31: =IF(A31="","",_xludf.TEXTJOIN("; ",TRUE,IF(SUMIFS($J:$J,$C:$C,C31,$B:$B,B31)>Settings!$B$9,"Weekly ordinary hrs >45",""),IF(SUMIFS(Claims!$H:$H,Claims!$C:$C,C31,Claims!$B:$B,B31)>Settings!$B$10,"Weekly OT >10",""),IF(AND(G31<>"Off",COUNTIFS($C:$C,C31,$A:$A,A31-1,$G:$G,"Night")>0),"Rest <12h after night shift",""),IF(J31>5,"Meal interval required",""))) -> #NAME? | O31: Pending
A32: =IF(1+1<=Settings!$B$7,Settings!$B$6+1,"") -> 46144 | B32: =IF(A32="","",A32-WEEKDAY(A32,2)+1) -> 46139 | C32: =IF(Employees!A12="","",Employees!A12) -> E009 | D32: =IF(C32="","",Employees!B12) -> Frank | E32: =IF(C32="","",Employees!C12) -> A | F32: =IF(A32="","",MOD(A32-Settings!$B$6,4)+1) -> 2 | G32: =IF(C32="","",INDEX(Rotation_Pattern!$B$4:$E$7,F32,MATCH(E32,{"A","B","C","D"},0))) -> Evening | H32: =IF(OR(G32="Off",G32=""),"",IF(G32="Day",TIME(6,0,0),IF(G32="Evening",TIME(14,0,0),TIME(22,0,0)))) -> 0.58333333 | I32: =IF(OR(G32="Off",G32=""),"",H32+TIME(Settings!$B$8,0,0)) -> 0.91666667 | J32: =IF(OR(G32="Off",G32=""),0,Settings!$B$8) -> 8 | K32: N | L32: =IF(A32="","",IF(COUNTIF(Public_Holidays!$A$4:$A$80,A32)>0,"Y","N")) -> N | M32: =IF(A32="","",IF(WEEKDAY(A32,2)=7,"Y","N")) -> N | N32: =IF(A32="","",_xludf.TEXTJOIN("; ",TRUE,IF(SUMIFS($J:$J,$C:$C,C32,$B:$B,B32)>Settings!$B$9,"Weekly ordinary hrs >45",""),IF(SUMIFS(Claims!$H:$H,Claims!$C:$C,C32,Claims!$B:$B,B32)>Settings!$B$10,"Weekly OT >10",""),IF(AND(G32<>"Off",COUNTIFS($C:$C,C32,$A:$A,A32-1,$G:$G,"Night")>0),"Rest <12h after night shift",""),IF(J32>5,"Meal interval required",""))) -> #NAME? | O32: Pending
A33: =IF(1+1<=Settings!$B$7,Settings!$B$6+1,"") -> 46144 | B33: =IF(A33="","",A33-WEEKDAY(A33,2)+1) -> 46139 | C33: =IF(Employees!A13="","",Employees!A13) | D33: =IF(C33="","",Employees!B13) | E33: =IF(C33="","",Employees!C13) | F33: =IF(A33="","",MOD(A33-Settings!$B$6,4)+1) -> 2 | G33: =IF(C33="","",INDEX(Rotation_Pattern!$B$4:$E$7,F33,MATCH(E33,{"A","B","C","D"},0))) | H33: =IF(OR(G33="Off",G33=""),"",IF(G33="Day",TIME(6,0,0),IF(G33="Evening",TIME(14,0,0),TIME(22,0,0)))) | I33: =IF(OR(G33="Off",G33=""),"",H33+TIME(Settings!$B$8,0,0)) | J33: =IF(OR(G33="Off",G33=""),0,Settings!$B$8) -> 0 | K33: N | L33: =IF(A33="","",IF(COUNTIF(Public_Holidays!$A$4:$A$80,A33)>0,"Y","N")) -> N | M33: =IF(A33="","",IF(WEEKDAY(A33,2)=7,"Y","N")) -> N | N33: =IF(A33="","",_xludf.TEXTJOIN("; ",TRUE,IF(SUMIFS($J:$J,$C:$C,C33,$B:$B,B33)>Settings!$B$9,"Weekly ordinary hrs >45",""),IF(SUMIFS(Claims!$H:$H,Claims!$C:$C,C33,Claims!$B:$B,B33)>Settings!$B$10,"Weekly OT >10",""),IF(AND(G33<>"Off",COUNTIFS($C:$C,C33,$A:$A,A33-1,$G:$G,"Night")>0),"Rest <12h after night shift",""),IF(J33>5,"Meal interval required",""))) -> #NAME? | O33: Pending
A34: =IF(1+1<=Settings!$B$7,Settings!$B$6+1,"") -> 46144 | B34: =IF(A34="","",A34-WEEKDAY(A34,2)+1) -> 46139 | C34: =IF(Employees!A14="","",Employees!A14) | D34: =IF(C34="","",Employees!B14) | E34: =IF(C34="","",Employees!C14) | F34: =IF(A34="","",MOD(A34-Settings!$B$6,4)+1) -> 2 | G34: =IF(C34="","",INDEX(Rotation_Pattern!$B$4:$E$7,F34,MATCH(E34,{"A","B","C","D"},0))) | H34: =IF(OR(G34="Off",G34=""),"",IF(G34="Day",TIME(6,0,0),IF(G34="Evening",TIME(14,0,0),TIME(22,0,0)))) | I34: =IF(OR(G34="Off",G34=""),"",H34+TIME(Settings!$B$8,0,0)) | J34: =IF(OR(G34="Off",G34=""),0,Settings!$B$8) -> 0 | K34: N | L34: =IF(A34="","",IF(COUNTIF(Public_Holidays!$A$4:$A$80,A34)>0,"Y","N")) -> N | M34: =IF(A34="","",IF(WEEKDAY(A34,2)=7,"Y","N")) -> N | N34: =IF(A34="","",_xludf.TEXTJOIN("; ",TRUE,IF(SUMIFS($J:$J,$C:$C,C34,$B:$B,B34)>Settings!$B$9,"Weekly ordinary hrs >45",""),IF(SUMIFS(Claims!$H:$H,Claims!$C:$C,C34,Claims!$B:$B,B34)>Settings!$B$10,"Weekly OT >10",""),IF(AND(G34<>"Off",COUNTIFS($C:$C,C34,$A:$A,A34-1,$G:$G,"Night")>0),"Rest <12h after night shift",""),IF(J34>5,"Meal interval required",""))) -> #NAME? | O34: Pending
A35: =IF(1+1<=Settings!$B$7,Settings!$B$6+1,"") -> 46144 | B35: =IF(A35="","",A35-WEEKDAY(A35,2)+1) -> 46139 | C35: =IF(Employees!A15="","",Employees!A15) | D35: =IF(C35="","",Employees!B15) | E35: =IF(C35="","",Employees!C15) | F35: =IF(A35="","",MOD(A35-Settings!$B$6,4)+1) -> 2 | G35: =IF(C35="","",INDEX(Rotation_Pattern!$B$4:$E$7,F35,MATCH(E35,{"A","B","C","D"},0))) | H35: =IF(OR(G35="Off",G35=""),"",IF(G35="Day",TIME(6,0,0),IF(G35="Evening",TIME(14,0,0),TIME(22,0,0)))) | I35: =IF(OR(G35="Off",G35=""),"",H35+TIME(Settings!$B$8,0,0)) | J35: =IF(OR(G35="Off",G35=""),0,Settings!$B$8) -> 0 | K35: N | L35: =IF(A35="","",IF(COUNTIF(Public_Holidays!$A$4:$A$80,A35)>0,"Y","N")) -> N | M35: =IF(A35="","",IF(WEEKDAY(A35,2)=7,"Y","N")) -> N | N35: =IF(A35="","",_xludf.TEXTJOIN("; ",TRUE,IF(SUMIFS($J:$J,$C:$C,C35,$B:$B,B35)>Settings!$B$9,"Weekly ordinary hrs >45",""),IF(SUMIFS(Claims!$H:$H,Claims!$C:$C,C35,Claims!$B:$B,B35)>Settings!$B$10,"Weekly OT >10",""),IF(AND(G35<>"Off",COUNTIFS($C:$C,C35,$A:$A,A35-1,$G:$G,"Night")>0),"Rest <12h after night shift",""),IF(J35>5,"Meal interval required",""))) -> #NAME? | O35: Pending
... A43: =IF(1+1<=Settings!$B$7,Settings!$B$6+1,"") -> 46144 | B43: =IF(A43="","",A43-WEEKDAY(A43,2)+1) -> 46139 | C43: =IF(Employees!A23="","",Employees!A23) | D43: =IF(C43="","",Employees!B23) | E43: =IF(C43="","",Employees!C23) | F43: =IF(A43="","",MOD(A43-Settings!$B$6,4)+1) -> 2 | G43: =IF(C43="","",INDEX(Rotation_Pattern!$B$4:$E$7,F43,MATCH(E43,{"A","B","C","D"},0))) | H43: =IF(OR(G43="Off",G43=""),"",IF(G43="Day",TIME(6,0,0),IF(G43="Evening",TIME(14,0,0),TIME(22,0,0)))) | I43: =IF(OR(G43="Off",G43=""),"",H43+TIME(Settings!$B$8,0,0)) | J43: =IF(OR(G43="Off",G43=""),0,Settings!$B$8) -> 0 | K43: N | L43: =IF(A43="","",IF(COUNTIF(Public_Holidays!$A$4:$A$80,A43)>0,"Y","N")) -> N | M43: =IF(A43="","",IF(WEEKDAY(A43,2)=7,"Y","N")) -> N | N43: =IF(A43="","",_xludf.TEXTJOIN("; ",TRUE,IF(SUMIFS($J:$J,$C:$C,C43,$B:$B,B43)>Settings!$B$9,"Weekly ordinary hrs >45",""),IF(SUMIFS(Claims!$H:$H,Claims!$C:$C,C43,Claims!$B:$B,B43)>Settings!$B$10,"Weekly OT >10",""),IF(AND(G43<>"Off",COUNTIFS($C:$C,C43,$A:$A,A43-1,$G:$G,"Night")>0),"Rest <12h after night shift",""),IF(J43>5,"Meal interval required",""))) -> #NAME? | O43: Pending
A44: =IF(2+1<=Settings!$B$7,Settings!$B$6+2,"") -> 46145 | B44: =IF(A44="","",A44-WEEKDAY(A44,2)+1) -> 46139 | C44: =IF(Employees!A4="","",Employees!A4) -> E001 | D44: =IF(C44="","",Employees!B4) -> Musiwa Khavalani | E44: =IF(C44="","",Employees!C4) -> 0 | F44: =IF(A44="","",MOD(A44-Settings!$B$6,4)+1) -> 3 | G44: =IF(C44="","",INDEX(Rotation_Pattern!$B$4:$E$7,F44,MATCH(E44,{"A","B","C","D"},0))) -> #N/A | H44: =IF(OR(G44="Off",G44=""),"",IF(G44="Day",TIME(6,0,0),IF(G44="Evening",TIME(14,0,0),TIME(22,0,0)))) -> #N/A | I44: =IF(OR(G44="Off",G44=""),"",H44+TIME(Settings!$B$8,0,0)) -> #N/A | J44: =IF(OR(G44="Off",G44=""),0,Settings!$B$8) -> #N/A | K44: N | L44: =IF(A44="","",IF(COUNTIF(Public_Holidays!$A$4:$A$80,A44)>0,"Y","N")) -> N | M44: =IF(A44="","",IF(WEEKDAY(A44,2)=7,"Y","N")) -> Y | N44: =IF(A44="","",_xludf.TEXTJOIN("; ",TRUE,IF(SUMIFS($J:$J,$C:$C,C44,$B:$B,B44)>Settings!$B$9,"Weekly ordinary hrs >45",""),IF(SUMIFS(Claims!$H:$H,Claims!$C:$C,C44,Claims!$B:$B,B44)>Settings!$B$10,"Weekly OT >10",""),IF(AND(G44<>"Off",COUNTIFS($C:$C,C44,$A:$A,A44-1,$G:$G,"Night")>0),"Rest <12h after night shift",""),IF(J44>5,"Meal interval required",""))) -> #NAME? | O44: Pending
A45: =IF(2+1<=Settings!$B$7,Settings!$B$6+2,"") -> 46145 | B45: =IF(A45="","",A45-WEEKDAY(A45,2)+1) -> 46139 | C45: =IF(Employees!A5="","",Employees!A5) -> E002 | D45: =IF(C45="","",Employees!B5) -> Mpho Nembemhia | E45: =IF(C45="","",Employees!C5) -> B | F45: =IF(A45="","",MOD(A45-Settings!$B$6,4)+1) -> 3 | G45: =IF(C45="","",INDEX(Rotation_Pattern!$B$4:$E$7,F45,MATCH(E45,{"A","B","C","D"},0))) -> Evening | H45: =IF(OR(G45="Off",G45=""),"",IF(G45="Day",TIME(6,0,0),IF(G45="Evening",TIME(14,0,0),TIME(22,0,0)))) -> 0.58333333 | I45: =IF(OR(G45="Off",G45=""),"",H45+TIME(Settings!$B$8,0,0)) -> 0.91666667 | J45: =IF(OR(G45="Off",G45=""),0,Settings!$B$8) -> 8 | K45: N | L45: =IF(A45="","",IF(COUNTIF(Public_Holidays!$A$4:$A$80,A45)>0,"Y","N")) -> N | M45: =IF(A45="","",IF(WEEKDAY(A45,2)=7,"Y","N")) -> Y | N45: =IF(A45="","",_xludf.TEXTJOIN("; ",TRUE,IF(SUMIFS($J:$J,$C:$C,C45,$B:$B,B45)>Settings!$B$9,"Weekly ordinary hrs >45",""),IF(SUMIFS(Claims!$H:$H,Claims!$C:$C,C45,Claims!$B:$B,B45)>Settings!$B$10,"Weekly OT >10",""),IF(AND(G45<>"Off",COUNTIFS($C:$C,C45,$A:$A,A45-1,$G:$G,"Night")>0),"Rest <12h after night shift",""),IF(J45>5,"Meal interval required",""))) -> #NAME? | O45: Pending
A46: =IF(2+1<=Settings!$B$7,Settings!$B$6+2,"") -> 46145 | B46: =IF(A46="","",A46-WEEKDAY(A46,2)+1) -> 46139 | C46: =IF(Employees!A6="","",Employees!A6) -> E003 | D46: =IF(C46="","",Employees!B6) -> Dimpho Makhafola | E46: =IF(C46="","",Employees!C6) -> C | F46: =IF(A46="","",MOD(A46-Settings!$B$6,4)+1) -> 3 | G46: =IF(C46="","",INDEX(Rotation_Pattern!$B$4:$E$7,F46,MATCH(E46,{"A","B","C","D"},0))) -> Day | H46: =IF(OR(G46="Off",G46=""),"",IF(G46="Day",TIME(6,0,0),IF(G46="Evening",TIME(14,0,0),TIME(22,0,0)))) -> 0.25 | I46: =IF(OR(G46="Off",G46=""),"",H46+TIME(Settings!$B$8,0,0)) -> 0.58333333 | J46: =IF(OR(G46="Off",G46=""),0,Settings!$B$8) -> 8 | K46: N | L46: =IF(A46="","",IF(COUNTIF(Public_Holidays!$A$4:$A$80,A46)>0,"Y","N")) -> N | M46: =IF(A46="","",IF(WEEKDAY(A46,2)=7,"Y","N")) -> Y | N46: =IF(A46="","",_xludf.TEXTJOIN("; ",TRUE,IF(SUMIFS($J:$J,$C:$C,C46,$B:$B,B46)>Settings!$B$9,"Weekly ordinary hrs >45",""),IF(SUMIFS(Claims!$H:$H,Claims!$C:$C,C46,Claims!$B:$B,B46)>Settings!$B$10,"Weekly OT >10",""),IF(AND(G46<>"Off",COUNTIFS($C:$C,C46,$A:$A,A46-1,$G:$G,"Night")>0),"Rest <12h after night shift",""),IF(J46>5,"Meal interval required",""))) -> #NAME? | O46: Pending
A47: =IF(2+1<=Settings!$B$7,Settings!$B$6+2,"") -> 46145 | B47: =IF(A47="","",A47-WEEKDAY(A47,2)+1) -> 46139 | C47: =IF(Employees!A7="","",Employees!A7) -> E004 | D47: =IF(C47="","",Employees!B7) -> Bashii Fall | E47: =IF(C47="","",Employees!C7) -> D | F47: =IF(A47="","",MOD(A47-Settings!$B$6,4)+1) -> 3 | G47: =IF(C47="","",INDEX(Rotation_Pattern!$B$4:$E$7,F47,MATCH(E47,{"A","B","C","D"},0))) -> Off | H47: =IF(OR(G47="Off",G47=""),"",IF(G47="Day",TIME(6,0,0),IF(G47="Evening",TIME(14,0,0),TIME(22,0,0)))) | I47: =IF(OR(G47="Off",G47=""),"",H47+TIME(Settings!$B$8,0,0)) | J47: =IF(OR(G47="Off",G47=""),0,Settings!$B$8) -> 0 | K47: N | L47: =IF(A47="","",IF(COUNTIF(Public_Holidays!$A$4:$A$80,A47)>0,"Y","N")) -> N | M47: =IF(A47="","",IF(WEEKDAY(A47,2)=7,"Y","N")) -> Y | N47: =IF(A47="","",_xludf.TEXTJOIN("; ",TRUE,IF(SUMIFS($J:$J,$C:$C,C47,$B:$B,B47)>Settings!$B$9,"Weekly ordinary hrs >45",""),IF(SUMIFS(Claims!$H:$H,Claims!$C:$C,C47,Claims!$B:$B,B47)>Settings!$B$10,"Weekly OT >10",""),IF(AND(G47<>"Off",COUNTIFS($C:$C,C47,$A:$A,A47-1,$G:$G,"Night")>0),"Rest <12h after night shift",""),IF(J47>5,"Meal interval required",""))) -> #NAME? | O47: Pending
A48: =IF(2+1<=Settings!$B$7,Settings!$B$6+2,"") -> 46145 | B48: =IF(A48="","",A48-WEEKDAY(A48,2)+1) -> 46139 | C48: =IF(Employees!A8="","",Employees!A8) -> E005 | D48: =IF(C48="","",Employees!B8) -> Lesego Aphane | E48: =IF(C48="","",Employees!C8) -> A | F48: =IF(A48="","",MOD(A48-Settings!$B$6,4)+1) -> 3 | G48: =IF(C48="","",INDEX(Rotation_Pattern!$B$4:$E$7,F48,MATCH(E48,{"A","B","C","D"},0))) -> Night | H48: =IF(OR(G48="Off",G48=""),"",IF(G48="Day",TIME(6,0,0),IF(G48="Evening",TIME(14,0,0),TIME(22,0,0)))) -> 0.91666667 | I48: =IF(OR(G48="Off",G48=""),"",H48+TIME(Settings!$B$8,0,0)) -> 1.25 | J48: =IF(OR(G48="Off",G48=""),0,Settings!$B$8) -> 8 | K48: N | L48: =IF(A48="","",IF(COUNTIF(Public_Holidays!$A$4:$A$80,A48)>0,"Y","N")) -> N | M48: =IF(A48="","",IF(WEEKDAY(A48,2)=7,"Y","N")) -> Y | N48: =IF(A48="","",_xludf.TEXTJOIN("; ",TRUE,IF(SUMIFS($J:$J,$C:$C,C48,$B:$B,B48)>Settings!$B$9,"Weekly ordinary hrs >45",""),IF(SUMIFS(Claims!$H:$H,Claims!$C:$C,C48,Claims!$B:$B,B48)>Settings!$B$10,"Weekly OT >10",""),IF(AND(G48<>"Off",COUNTIFS($C:$C,C48,$A:$A,A48-1,$G:$G,"Night")>0),"Rest <12h after night shift",""),IF(J48>5,"Meal interval required",""))) -> #NAME? | O48: Pending
A49: =IF(2+1<=Settings!$B$7,Settings!$B$6+2,"") -> 46145 | B49: =IF(A49="","",A49-WEEKDAY(A49,2)+1) -> 46139 | C49: =IF(Employees!A9="","",Employees!A9) -> E006 | D49: =IF(C49="","",Employees!B9) -> Nhalnahla | E49: =IF(C49="","",Employees!C9) -> B | F49: =IF(A49="","",MOD(A49-Settings!$B$6,4)+1) -> 3 | G49: =IF(C49="","",INDEX(Rotation_Pattern!$B$4:$E$7,F49,MATCH(E49,{"A","B","C","D"},0))) -> Evening | H49: =IF(OR(G49="Off",G49=""),"",IF(G49="Day",TIME(6,0,0),IF(G49="Evening",TIME(14,0,0),TIME(22,0,0)))) -> 0.58333333 | I49: =IF(OR(G49="Off",G49=""),"",H49+TIME(Settings!$B$8,0,0)) -> 0.91666667 | J49: =IF(OR(G49="Off",G49=""),0,Settings!$B$8) -> 8 | K49: N | L49: =IF(A49="","",IF(COUNTIF(Public_Holidays!$A$4:$A$80,A49)>0,"Y","N")) -> N | M49: =IF(A49="","",IF(WEEKDAY(A49,2)=7,"Y","N")) -> Y | N49: =IF(A49="","",_xludf.TEXTJOIN("; ",TRUE,IF(SUMIFS($J:$J,$C:$C,C49,$B:$B,B49)>Settings!$B$9,"Weekly ordinary hrs >45",""),IF(SUMIFS(Claims!$H:$H,Claims!$C:$C,C49,Claims!$B:$B,B49)>Settings!$B$10,"Weekly OT >10",""),IF(AND(G49<>"Off",COUNTIFS($C:$C,C49,$A:$A,A49-1,$G:$G,"Night")>0),"Rest <12h after night shift",""),IF(J49>5,"Meal interval required",""))) -> #NAME? | O49: Pending
A50: =IF(2+1<=Settings!$B$7,Settings!$B$6+2,"") -> 46145 | B50: =IF(A50="","",A50-WEEKDAY(A50,2)+1) -> 46139 | C50: =IF(Employees!A10="","",Employees!A10) -> E007 | D50: =IF(C50="","",Employees!B10) -> Joe | E50: =IF(C50="","",Employees!C10) -> C | F50: =IF(A50="","",MOD(A50-Settings!$B$6,4)+1) -> 3 | G50: =IF(C50="","",INDEX(Rotation_Pattern!$B$4:$E$7,F50,MATCH(E50,{"A","B","C","D"},0))) -> Day | H50: =IF(OR(G50="Off",G50=""),"",IF(G50="Day",TIME(6,0,0),IF(G50="Evening",TIME(14,0,0),TIME(22,0,0)))) -> 0.25 | I50: =IF(OR(G50="Off",G50=""),"",H50+TIME(Settings!$B$8,0,0)) -> 0.58333333 | J50: =IF(OR(G50="Off",G50=""),0,Settings!$B$8) -> 8 | K50: N | L50: =IF(A50="","",IF(COUNTIF(Public_Holidays!$A$4:$A$80,A50)>0,"Y","N")) -> N | M50: =IF(A50="","",IF(WEEKDAY(A50,2)=7,"Y","N")) -> Y | N50: =IF(A50="","",_xludf.TEXTJOIN("; ",TRUE,IF(SUMIFS($J:$J,$C:$C,C50,$B:$B,B50)>Settings!$B$9,"Weekly ordinary hrs >45",""),IF(SUMIFS(Claims!$H:$H,Claims!$C:$C,C50,Claims!$B:$B,B50)>Settings!$B$10,"Weekly OT >10",""),IF(AND(G50<>"Off",COUNTIFS($C:$C,C50,$A:$A,A50-1,$G:$G,"Night")>0),"Rest <12h after night shift",""),IF(J50>5,"Meal interval required",""))) -> #NAME? | O50: Pending
A51: =IF(2+1<=Settings!$B$7,Settings!$B$6+2,"") -> 46145 | B51: =IF(A51="","",A51-WEEKDAY(A51,2)+1) -> 46139 | C51: =IF(Employees!A11="","",Employees!A11) -> E008 | D51: =IF(C51="","",Employees!B11) -> Tim | E51: =IF(C51="","",Employees!C11) -> D | F51: =IF(A51="","",MOD(A51-Settings!$B$6,4)+1) -> 3 | G51: =IF(C51="","",INDEX(Rotation_Pattern!$B$4:$E$7,F51,MATCH(E51,{"A","B","C","D"},0))) -> Off | H51: =IF(OR(G51="Off",G51=""),"",IF(G51="Day",TIME(6,0,0),IF(G51="Evening",TIME(14,0,0),TIME(22,0,0)))) | I51: =IF(OR(G51="Off",G51=""),"",H51+TIME(Settings!$B$8,0,0)) | J51: =IF(OR(G51="Off",G51=""),0,Settings!$B$8) -> 0 | K51: N | L51: =IF(A51="","",IF(COUNTIF(Public_Holidays!$A$4:$A$80,A51)>0,"Y","N")) -> N | M51: =IF(A51="","",IF(WEEKDAY(A51,2)=7,"Y","N")) -> Y | N51: =IF(A51="","",_xludf.TEXTJOIN("; ",TRUE,IF(SUMIFS($J:$J,$C:$C,C51,$B:$B,B51)>Settings!$B$9,"Weekly ordinary hrs >45",""),IF(SUMIFS(Claims!$H:$H,Claims!$C:$C,C51,Claims!$B:$B,B51)>Settings!$B$10,"Weekly OT >10",""),IF(AND(G51<>"Off",COUNTIFS($C:$C,C51,$A:$A,A51-1,$G:$G,"Night")>0),"Rest <12h after night shift",""),IF(J51>5,"Meal interval required",""))) -> #NAME? | O51: Pending
A52: =IF(2+1<=Settings!$B$7,Settings!$B$6+2,"") -> 46145 | B52: =IF(A52="","",A52-WEEKDAY(A52,2)+1) -> 46139 | C52: =IF(Employees!A12="","",Employees!A12) -> E009 | D52: =IF(C52="","",Employees!B12) -> Frank | E52: =IF(C52="","",Employees!C12) -> A | F52: =IF(A52="","",MOD(A52-Settings!$B$6,4)+1) -> 3 | G52: =IF(C52="","",INDEX(Rotation_Pattern!$B$4:$E$7,F52,MATCH(E52,{"A","B","C","D"},0))) -> Night | H52: =IF(OR(G52="Off",G52=""),"",IF(G52="Day",TIME(6,0,0),IF(G52="Evening",TIME(14,0,0),TIME(22,0,0)))) -> 0.91666667 | I52: =IF(OR(G52="Off",G52=""),"",H52+TIME(Settings!$B$8,0,0)) -> 1.25 | J52: =IF(OR(G52="Off",G52=""),0,Settings!$B$8) -> 8 | K52: N | L52: =IF(A52="","",IF(COUNTIF(Public_Holidays!$A$4:$A$80,A52)>0,"Y","N")) -> N | M52: =IF(A52="","",IF(WEEKDAY(A52,2)=7,"Y","N")) -> Y | N52: =IF(A52="","",_xludf.TEXTJOIN("; ",TRUE,IF(SUMIFS($J:$J,$C:$C,C52,$B:$B,B52)>Settings!$B$9,"Weekly ordinary hrs >45",""),IF(SUMIFS(Claims!$H:$H,Claims!$C:$C,C52,Claims!$B:$B,B52)>Settings!$B$10,"Weekly OT >10",""),IF(AND(G52<>"Off",COUNTIFS($C:$C,C52,$A:$A,A52-1,$G:$G,"Night")>0),"Rest <12h after night shift",""),IF(J52>5,"Meal interval required",""))) -> #NAME? | O52: Pending
A53: =IF(2+1<=Settings!$B$7,Settings!$B$6+2,"") -> 46145 | B53: =IF(A53="","",A53-WEEKDAY(A53,2)+1) -> 46139 | C53: =IF(Employees!A13="","",Employees!A13) | D53: =IF(C53="","",Employees!B13) | E53: =IF(C53="","",Employees!C13) | F53: =IF(A53="","",MOD(A53-Settings!$B$6,4)+1) -> 3 | G53: =IF(C53="","",INDEX(Rotation_Pattern!$B$4:$E$7,F53,MATCH(E53,{"A","B","C","D"},0))) | H53: =IF(OR(G53="Off",G53=""),"",IF(G53="Day",TIME(6,0,0),IF(G53="Evening",TIME(14,0,0),TIME(22,0,0)))) | I53: =IF(OR(G53="Off",G53=""),"",H53+TIME(Settings!$B$8,0,0)) | J53: =IF(OR(G53="Off",G53=""),0,Settings!$B$8) -> 0 | K53: N | L53: =IF(A53="","",IF(COUNTIF(Public_Holidays!$A$4:$A$80,A53)>0,"Y","N")) -> N | M53: =IF(A53="","",IF(WEEKDAY(A53,2)=7,"Y","N")) -> Y | N53: =IF(A53="","",_xludf.TEXTJOIN("; ",TRUE,IF(SUMIFS($J:$J,$C:$C,C53,$B:$B,B53)>Settings!$B$9,"Weekly ordinary hrs >45",""),IF(SUMIFS(Claims!$H:$H,Claims!$C:$C,C53,Claims!$B:$B,B53)>Settings!$B$10,"Weekly OT >10",""),IF(AND(G53<>"Off",COUNTIFS($C:$C,C53,$A:$A,A53-1,$G:$G,"Night")>0),"Rest <12h after night shift",""),IF(J53>5,"Meal interval required",""))) -> #NAME? | O53: Pending
A54: =IF(2+1<=Settings!$B$7,Settings!$B$6+2,"") -> 46145 | B54: =IF(A54="","",A54-WEEKDAY(A54,2)+1) -> 46139 | C54: =IF(Employees!A14="","",Employees!A14) | D54: =IF(C54="","",Employees!B14) | E54: =IF(C54="","",Employees!C14) | F54: =IF(A54="","",MOD(A54-Settings!$B$6,4)+1) -> 3 | G54: =IF(C54="","",INDEX(Rotation_Pattern!$B$4:$E$7,F54,MATCH(E54,{"A","B","C","D"},0))) | H54: =IF(OR(G54="Off",G54=""),"",IF(G54="Day",TIME(6,0,0),IF(G54="Evening",TIME(14,0,0),TIME(22,0,0)))) | I54: =IF(OR(G54="Off",G54=""),"",H54+TIME(Settings!$B$8,0,0)) | J54: =IF(OR(G54="Off",G54=""),0,Settings!$B$8) -> 0 | K54: N | L54: =IF(A54="","",IF(COUNTIF(Public_Holidays!$A$4:$A$80,A54)>0,"Y","N")) -> N | M54: =IF(A54="","",IF(WEEKDAY(A54,2)=7,"Y","N")) -> Y | N54: =IF(A54="","",_xludf.TEXTJOIN("; ",TRUE,IF(SUMIFS($J:$J,$C:$C,C54,$B:$B,B54)>Settings!$B$9,"Weekly ordinary hrs >45",""),IF(SUMIFS(Claims!$H:$H,Claims!$C:$C,C54,Claims!$B:$B,B54)>Settings!$B$10,"Weekly OT >10",""),IF(AND(G54<>"Off",COUNTIFS($C:$C,C54,$A:$A,A54-1,$G:$G,"Night")>0),"Rest <12h after night shift",""),IF(J54>5,"Meal interval required",""))) -> #NAME? | O54: Pending
...

Sheet Claims
A1: Shift Hours Claim Sheet
A3: Claim Date | B3: Week Start | C3: Employee ID | D3: Employee Name | E3: Team | F3: Shift Type | G3: Claimed Hours | H3: Overtime Hours | I3: Normal Hours | J3: Sunday Hours | K3: Public Holiday Hours | L3: Standby? | M3: Standby Amount | N3: Night Hours | O3: Night Allowance | P3: Hourly Rate | Q3: Normal Pay | R3: Overtime Pay | S3: Sunday Pay | T3: Public Holiday Pay | U3: Total Claim | V3: Approval Status | W3: Compliance Flags | X3: Manager Notes
A4: =Auto_Roster!A4 -> 46143 | B4: =Auto_Roster!B4 -> 46139 | C4: =Auto_Roster!C4 -> E001 | D4: =Auto_Roster!D4 -> Musiwa Khavalani | E4: A | F4: =Auto_Roster!G4 -> #N/A | G4: =Auto_Roster!J4 -> #N/A | H4: =IF(G4>Settings!$B$19,G4-Settings!$B$19,0) -> #N/A | I4: =MAX(0,G4-H4) -> #N/A | J4: =IF(Auto_Roster!M4="Y",G4,0) -> 0 | K4: =IF(Auto_Roster!L4="Y",G4,0) -> #N/A | L4: =Auto_Roster!K4 -> N | M4: =IF(L4="Y",Settings!$B$16,0) -> 0 | N4: =IF(F4="Night",G4,0) -> #N/A | O4: =N4*Settings!$B$17 -> #N/A | P4: =IFERROR(VLOOKUP(C4,Employees!$A$4:$E$103,5,FALSE),Settings!$B$18) -> 100 | Q4: =I4*P4 -> #N/A | R4: =H4*P4*Settings!$B$13 -> #N/A | S4: =J4*P4*(Settings!$B$14-1) -> 0 | T4: =K4*P4*(Settings!$B$15-1) -> #N/A | U4: =SUM(Q4:T4)+M4+O4 -> #N/A | V4: =Auto_Roster!O4 -> Pending | W4: =_xludf.TEXTJOIN("; ",TRUE,Auto_Roster!N4,IF(G4>Settings!$B$19,"Approval required > standard hours",""),IF(AND(F4<>"Off",G4=0),"Missing claimed hours","")) -> #NAME?
A5: =Auto_Roster!A5 -> 46143 | B5: =Auto_Roster!B5 -> 46139 | C5: =Auto_Roster!C5 -> E002 | D5: =Auto_Roster!D5 -> Mpho Nembemhia | E5: =Auto_Roster!E5 -> B | F5: =Auto_Roster!G5 -> Off | G5: =Auto_Roster!J5 -> 0 | H5: =IF(G5>Settings!$B$19,G5-Settings!$B$19,0) -> 0 | I5: =MAX(0,G5-H5) -> 0 | J5: =IF(Auto_Roster!M5="Y",G5,0) -> 0 | K5: =IF(Auto_Roster!L5="Y",G5,0) -> 0 | L5: =Auto_Roster!K5 -> N | M5: =IF(L5="Y",Settings!$B$16,0) -> 0 | N5: =IF(F5="Night",G5,0) -> 0 | O5: =N5*Settings!$B$17 -> 0 | P5: =IFERROR(VLOOKUP(C5,Employees!$A$4:$E$103,5,FALSE),Settings!$B$18) -> 100 | Q5: =I5*P5 -> 0 | R5: =H5*P5*Settings!$B$13 -> 0 | S5: =J5*P5*(Settings!$B$14-1) -> 0 | T5: =K5*P5*(Settings!$B$15-1) -> 0 | U5: =SUM(Q5:T5)+M5+O5 -> 0 | V5: =Auto_Roster!O5 -> Pending | W5: =_xludf.TEXTJOIN("; ",TRUE,Auto_Roster!N5,IF(G5>Settings!$B$19,"Approval required > standard hours",""),IF(AND(F5<>"Off",G5=0),"Missing claimed hours","")) -> #NAME?
A6: =Auto_Roster!A6 -> 46143 | B6: =Auto_Roster!B6 -> 46139 | C6: =Auto_Roster!C6 -> E003 | D6: =Auto_Roster!D6 -> Dimpho Makhafola | E6: =Auto_Roster!E6 -> C | F6: =Auto_Roster!G6 -> Evening | G6: =Auto_Roster!J6 -> 8 | H6: =IF(G6>Settings!$B$19,G6-Settings!$B$19,0) -> 0 | I6: =MAX(0,G6-H6) -> 8 | J6: =IF(Auto_Roster!M6="Y",G6,0) -> 0 | K6: =IF(Auto_Roster!L6="Y",G6,0) -> 8 | L6: =Auto_Roster!K6 -> N | M6: =IF(L6="Y",Settings!$B$16,0) -> 0 | N6: =IF(F6="Night",G6,0) -> 0 | O6: =N6*Settings!$B$17 -> 0 | P6: =IFERROR(VLOOKUP(C6,Employees!$A$4:$E$103,5,FALSE),Settings!$B$18) -> 100 | Q6: =I6*P6 -> 800 | R6: =H6*P6*Settings!$B$13 -> 0 | S6: =J6*P6*(Settings!$B$14-1) -> 0 | T6: =K6*P6*(Settings!$B$15-1) -> 800 | U6: =SUM(Q6:T6)+M6+O6 -> 1600 | V6: =Auto_Roster!O6 -> Pending | W6: =_xludf.TEXTJOIN("; ",TRUE,Auto_Roster!N6,IF(G6>Settings!$B$19,"Approval required > standard hours",""),IF(AND(F6<>"Off",G6=0),"Missing claimed hours","")) -> #NAME?
A7: =Auto_Roster!A7 -> 46143 | B7: =Auto_Roster!B7 -> 46139 | C7: =Auto_Roster!C7 -> E004 | D7: =Auto_Roster!D7 -> Bashii Fall | E7: =Auto_Roster!E7 -> D | F7: =Auto_Roster!G7 -> Night | G7: =Auto_Roster!J7 -> 8 | H7: =IF(G7>Settings!$B$19,G7-Settings!$B$19,0) -> 0 | I7: =MAX(0,G7-H7) -> 8 | J7: =IF(Auto_Roster!M7="Y",G7,0) -> 0 | K7: =IF(Auto_Roster!L7="Y",G7,0) -> 8 | L7: =Auto_Roster!K7 -> N | M7: =IF(L7="Y",Settings!$B$16,0) -> 0 | N7: =IF(F7="Night",G7,0) -> 8 | O7: =N7*Settings!$B$17 -> 0 | P7: =IFERROR(VLOOKUP(C7,Employees!$A$4:$E$103,5,FALSE),Settings!$B$18) -> 100 | Q7: =I7*P7 -> 800 | R7: =H7*P7*Settings!$B$13 -> 0 | S7: =J7*P7*(Settings!$B$14-1) -> 0 | T7: =K7*P7*(Settings!$B$15-1) -> 800 | U7: =SUM(Q7:T7)+M7+O7 -> 1600 | V7: =Auto_Roster!O7 -> Pending | W7: =_xludf.TEXTJOIN("; ",TRUE,Auto_Roster!N7,IF(G7>Settings!$B$19,"Approval required > standard hours",""),IF(AND(F7<>"Off",G7=0),"Missing claimed hours","")) -> #NAME?
A8: =Auto_Roster!A8 -> 46143 | B8: =Auto_Roster!B8 -> 46139 | C8: =Auto_Roster!C8 -> E005 | D8: =Auto_Roster!D8 -> Lesego Aphane | E8: =Auto_Roster!E8 -> A | F8: =Auto_Roster!G8 -> Day | G8: =Auto_Roster!J8 -> 8 | H8: =IF(G8>Settings!$B$19,G8-Settings!$B$19,0) -> 0 | I8: =MAX(0,G8-H8) -> 8 | J8: =IF(Auto_Roster!M8="Y",G8,0) -> 0 | K8: =IF(Auto_Roster!L8="Y",G8,0) -> 8 | L8: =Auto_Roster!K8 -> N | M8: =IF(L8="Y",Settings!$B$16,0) -> 0 | N8: =IF(F8="Night",G8,0) -> 0 | O8: =N8*Settings!$B$17 -> 0 | P8: =IFERROR(VLOOKUP(C8,Employees!$A$4:$E$103,5,FALSE),Settings!$B$18) -> 100 | Q8: =I8*P8 -> 800 | R8: =H8*P8*Settings!$B$13 -> 0 | S8: =J8*P8*(Settings!$B$14-1) -> 0 | T8: =K8*P8*(Settings!$B$15-1) -> 800 | U8: =SUM(Q8:T8)+M8+O8 -> 1600 | V8: =Auto_Roster!O8 -> Pending | W8: =_xludf.TEXTJOIN("; ",TRUE,Auto_Roster!N8,IF(G8>Settings!$B$19,"Approval required > standard hours",""),IF(AND(F8<>"Off",G8=0),"Missing claimed hours","")) -> #NAME?
A9: =Auto_Roster!A9 -> 46143 | B9: =Auto_Roster!B9 -> 46139 | C9: =Auto_Roster!C9 -> E006 | D9: =Auto_Roster!D9 -> Nhalnahla | E9: =Auto_Roster!E9 -> B | F9: =Auto_Roster!G9 -> Off | G9: =Auto_Roster!J9 -> 0 | H9: =IF(G9>Settings!$B$19,G9-Settings!$B$19,0) -> 0 | I9: =MAX(0,G9-H9) -> 0 | J9: =IF(Auto_Roster!M9="Y",G9,0) -> 0 | K9: =IF(Auto_Roster!L9="Y",G9,0) -> 0 | L9: =Auto_Roster!K9 -> N | M9: =IF(L9="Y",Settings!$B$16,0) -> 0 | N9: =IF(F9="Night",G9,0) -> 0 | O9: =N9*Settings!$B$17 -> 0 | P9: =IFERROR(VLOOKUP(C9,Employees!$A$4:$E$103,5,FALSE),Settings!$B$18) -> 100 | Q9: =I9*P9 -> 0 | R9: =H9*P9*Settings!$B$13 -> 0 | S9: =J9*P9*(Settings!$B$14-1) -> 0 | T9: =K9*P9*(Settings!$B$15-1) -> 0 | U9: =SUM(Q9:T9)+M9+O9 -> 0 | V9: =Auto_Roster!O9 -> Pending | W9: =_xludf.TEXTJOIN("; ",TRUE,Auto_Roster!N9,IF(G9>Settings!$B$19,"Approval required > standard hours",""),IF(AND(F9<>"Off",G9=0),"Missing claimed hours","")) -> #NAME?
A10: =Auto_Roster!A10 -> 46143 | B10: =Auto_Roster!B10 -> 46139 | C10: =Auto_Roster!C10 -> E007 | D10: =Auto_Roster!D10 -> Joe | E10: =Auto_Roster!E10 -> C | F10: =Auto_Roster!G10 -> Evening | G10: =Auto_Roster!J10 -> 8 | H10: =IF(G10>Settings!$B$19,G10-Settings!$B$19,0) -> 0 | I10: =MAX(0,G10-H10) -> 8 | J10: =IF(Auto_Roster!M10="Y",G10,0) -> 0 | K10: =IF(Auto_Roster!L10="Y",G10,0) -> 8 | L10: =Auto_Roster!K10 -> N | M10: =IF(L10="Y",Settings!$B$16,0) -> 0 | N10: =IF(F10="Night",G10,0) -> 0 | O10: =N10*Settings!$B$17 -> 0 | P10: =IFERROR(VLOOKUP(C10,Employees!$A$4:$E$103,5,FALSE),Settings!$B$18) -> 100 | Q10: =I10*P10 -> 800 | R10: =H10*P10*Settings!$B$13 -> 0 | S10: =J10*P10*(Settings!$B$14-1) -> 0 | T10: =K10*P10*(Settings!$B$15-1) -> 800 | U10: =SUM(Q10:T10)+M10+O10 -> 1600 | V10: =Auto_Roster!O10 -> Pending | W10: =_xludf.TEXTJOIN("; ",TRUE,Auto_Roster!N10,IF(G10>Settings!$B$19,"Approval required > standard hours",""),IF(AND(F10<>"Off",G10=0),"Missing claimed hours","")) -> #NAME?
A11: =Auto_Roster!A11 -> 46143 | B11: =Auto_Roster!B11 -> 46139 | C11: =Auto_Roster!C11 -> E008 | D11: =Auto_Roster!D11 -> Tim | E11: =Auto_Roster!E11 -> D | F11: =Auto_Roster!G11 -> Night | G11: =Auto_Roster!J11 -> 8 | H11: =IF(G11>Settings!$B$19,G11-Settings!$B$19,0) -> 0 | I11: =MAX(0,G11-H11) -> 8 | J11: =IF(Auto_Roster!M11="Y",G11,0) -> 0 | K11: =IF(Auto_Roster!L11="Y",G11,0) -> 8 | L11: =Auto_Roster!K11 -> N | M11: =IF(L11="Y",Settings!$B$16,0) -> 0 | N11: =IF(F11="Night",G11,0) -> 8 | O11: =N11*Settings!$B$17 -> 0 | P11: =IFERROR(VLOOKUP(C11,Employees!$A$4:$E$103,5,FALSE),Settings!$B$18) -> 100 | Q11: =I11*P11 -> 800 | R11: =H11*P11*Settings!$B$13 -> 0 | S11: =J11*P11*(Settings!$B$14-1) -> 0 | T11: =K11*P11*(Settings!$B$15-1) -> 800 | U11: =SUM(Q11:T11)+M11+O11 -> 1600 | V11: =Auto_Roster!O11 -> Pending | W11: =_xludf.TEXTJOIN("; ",TRUE,Auto_Roster!N11,IF(G11>Settings!$B$19,"Approval required > standard hours",""),IF(AND(F11<>"Off",G11=0),"Missing claimed hours","")) -> #NAME?
A12: =Auto_Roster!A12 -> 46143 | B12: =Auto_Roster!B12 -> 46139 | C12: =Auto_Roster!C12 -> E009 | D12: =Auto_Roster!D12 -> Frank | E12: =Auto_Roster!E12 -> A | F12: =Auto_Roster!G12 -> Day | G12: =Auto_Roster!J12 -> 8 | H12: =IF(G12>Settings!$B$19,G12-Settings!$B$19,0) -> 0 | I12: =MAX(0,G12-H12) -> 8 | J12: =IF(Auto_Roster!M12="Y",G12,0) -> 0 | K12: =IF(Auto_Roster!L12="Y",G12,0) -> 8 | L12: =Auto_Roster!K12 -> N | M12: =IF(L12="Y",Settings!$B$16,0) -> 0 | N12: =IF(F12="Night",G12,0) -> 0 | O12: =N12*Settings!$B$17 -> 0 | P12: =IFERROR(VLOOKUP(C12,Employees!$A$4:$E$103,5,FALSE),Settings!$B$18) -> 100 | Q12: =I12*P12 -> 800 | R12: =H12*P12*Settings!$B$13 -> 0 | S12: =J12*P12*(Settings!$B$14-1) -> 0 | T12: =K12*P12*(Settings!$B$15-1) -> 800 | U12: =SUM(Q12:T12)+M12+O12 -> 1600 | V12: =Auto_Roster!O12 -> Pending | W12: =_xludf.TEXTJOIN("; ",TRUE,Auto_Roster!N12,IF(G12>Settings!$B$19,"Approval required > standard hours",""),IF(AND(F12<>"Off",G12=0),"Missing claimed hours","")) -> #NAME?
A13: =Auto_Roster!A13 -> 46143 | B13: =Auto_Roster!B13 -> 46139 | C13: =Auto_Roster!C13 | D13: =Auto_Roster!D13 | E13: =Auto_Roster!E13 | F13: =Auto_Roster!G13 | G13: =Auto_Roster!J13 -> 0 | H13: =IF(G13>Settings!$B$19,G13-Settings!$B$19,0) -> 0 | I13: =MAX(0,G13-H13) -> 0 | J13: =IF(Auto_Roster!M13="Y",G13,0) -> 0 | K13: =IF(Auto_Roster!L13="Y",G13,0) -> 0 | L13: =Auto_Roster!K13 -> N | M13: =IF(L13="Y",Settings!$B$16,0) -> 0 | N13: =IF(F13="Night",G13,0) -> 0 | O13: =N13*Settings!$B$17 -> 0 | P13: =IFERROR(VLOOKUP(C13,Employees!$A$4:$E$103,5,FALSE),Settings!$B$18) -> 100 | Q13: =I13*P13 -> 0 | R13: =H13*P13*Settings!$B$13 -> 0 | S13: =J13*P13*(Settings!$B$14-1) -> 0 | T13: =K13*P13*(Settings!$B$15-1) -> 0 | U13: =SUM(Q13:T13)+M13+O13 -> 0 | V13: =Auto_Roster!O13 -> Pending | W13: =_xludf.TEXTJOIN("; ",TRUE,Auto_Roster!N13,IF(G13>Settings!$B$19,"Approval required > standard hours",""),IF(AND(F13<>"Off",G13=0),"Missing claimed hours","")) -> #NAME?
